<?xml version="1.0" ?>

<robot name="mybot_xacro" xmlns:controller="http://playerstage.sourceforge.net/gazebo/xmlschema/#controller" 
       xmlns:interface="http://playerstage.sourceforge.net/gazebo/xmlschema/#interface" 
       xmlns:sensor="http://playerstage.sourceforge.net/gazebo/xmlschema/#sensor" 
       xmlns:xacro="http://ros.org/wiki/xacro">
  
  <!-- KINECT ATTACHMENT -->
  <joint name="camera_rgb_joint" type="fixed">
    <origin rpy="0 0 0" xyz="0.028 -0.0125 0.075"/>
    <parent link="kinect_base_link"/>
    <child link="camera_rgb_frame"/>
  </joint>
  <link name="camera_rgb_frame">
    <inertial>
      <mass value="0.001"/>
      <origin xyz="0 0 0"/>
      <inertia ixx="0.0001" ixy="0.0" ixz="0.0" iyy="0.0001" iyz="0.0" izz="0.0001"/>
    </inertial>
    
  </link>
  <joint name="camera_rgb_optical_joint" type="fixed">
    <origin rpy="-1.57079632679 0 -1.57079632679" xyz="0 0 0"/>
    <parent link="camera_rgb_frame"/>
    <child link="camera_rgb_optical_frame"/>
  </joint>
  <link name="camera_rgb_optical_frame">
    <inertial>
      <mass value="0.001"/>
      <origin xyz="0 0 0"/>
      <inertia ixx="0.0001" ixy="0.0" ixz="0.0" iyy="0.0001" iyz="0.0" izz="0.0001"/>
    </inertial>
  </link>
  
  <joint name="camera_joint" type="fixed">
    <origin rpy="0 0 0" xyz="-0.031 0.0125 -0.016"/>
    <parent link="camera_rgb_frame"/>
    <child link="camera_link"/>
  </joint>
  
  <link name="camera_link">
    <visual>
      <!--origin xyz="0 0 0" rpy="0 0 ${M_PI/2}"/-->
      <origin rpy="0 0 0" xyz="0 0 0"/>
      <geometry>
        <mesh filename="package://a_diff_description/meshes/kinect.dae"/>
      </geometry>
    </visual>
    <collision>
      <origin rpy="0 0 0" xyz="0.0 0.0 0.0"/>
      <geometry>
        <box size="0.07271 0.27794 0.073"/>
      </geometry>
    </collision>
    <inertial>
      <mass value="0.001"/>
      <origin xyz="0 0 0"/>
      <inertia ixx="0.0001" ixy="0.0" ixz="0.0" iyy="0.0001" iyz="0.0" izz="0.0001"/>
    </inertial>
  </link>
  
  <joint name="camera_depth_joint" type="fixed">
    <origin rpy="0 0 0" xyz="0 0.025 0"/>
    <parent link="camera_rgb_frame"/>
    <child link="camera_depth_frame"/>
  </joint>
  <link name="camera_depth_frame">
    <inertial>
      <mass value="0.001"/>
      <origin xyz="0 0 0"/>
      <inertia ixx="0.0001" ixy="0.0" ixz="0.0" iyy="0.0001" iyz="0.0" izz="0.0001"/>
    </inertial>
  </link>
  <joint name="camera_depth_optical_joint" type="fixed">
    <origin rpy="-1.57079632679 0 -1.57079632679" xyz="0 0 0"/>
    <parent link="camera_depth_frame"/>
    <child link="camera_depth_optical_frame"/>
  </joint>
  <link name="camera_depth_optical_frame">
    <inertial>
      <mass value="0.001"/>
      <origin xyz="0 0 0"/>
      <inertia ixx="0.0001" ixy="0.0" ixz="0.0" iyy="0.0001" iyz="0.0" izz="0.0001"/>
    </inertial>
  </link>
  
  <gazebo reference="camera_link">
    <sensor name="camera" type="depth">
      <always_on>true</always_on>
      <update_rate>20.0</update_rate>
      <camera>
        <horizontal_fov>1.0471975512</horizontal_fov>
        <image>
          <format>R8G8B8</format>
          <width>640</width>
          <height>480</height>
        </image>
        <clip>
          <near>0.05</near>
          <far>8.0</far>
        </clip>
      </camera>
      <plugin filename="libgazebo_ros_openni_kinect.so" name="kinect_camera_controller">
        <cameraName>camera</cameraName>
        <alwaysOn>true</alwaysOn>
        <updateRate>10</updateRate>
        <imageTopicName>rgb/image_raw</imageTopicName>
        <depthImageTopicName>depth/image_raw</depthImageTopicName>
        <pointCloudTopicName>depth/points</pointCloudTopicName>
        <cameraInfoTopicName>rgb/camera_info</cameraInfoTopicName>
        <depthImageCameraInfoTopicName>depth/camera_info</depthImageCameraInfoTopicName>
        <frameName>camera_depth_optical_frame</frameName>
        <baseline>0.1</baseline>
        <distortion_k1>0.0</distortion_k1>
        <distortion_k2>0.0</distortion_k2>
        <distortion_k3>0.0</distortion_k3>
        <distortion_t1>0.0</distortion_t1>
        <distortion_t2>0.0</distortion_t2>
        <pointCloudCutoff>0.4</pointCloudCutoff>
      </plugin>
    </sensor>
  </gazebo>
  
  <!-- LASER ATTACHMENT -->
  <link name="laser">
    <collision>
      <origin rpy="0 0 0" xyz="0 0 0"/>
      <geometry>
        <box size="0.1 0.1 0.1"/>
      </geometry>
    </collision>
    <visual>
      <origin rpy="0 0 0" xyz="0 0 0"/>
      <geometry>
        <mesh filename="package://a_diff_description/meshes/hokuyo.dae"/>
      </geometry>
    </visual>
    <inertial>
      <mass value="1e-5"/>
      <origin rpy="0 0 0" xyz="0 0 0"/>
      <inertia ixx="1e-6" ixy="0" ixz="0" iyy="1e-6" iyz="0" izz="1e-6"/>
    </inertial>
  </link>
  <joint name="laser_joint" type="fixed">
    <axis xyz="0 0 3.14"/>
    <origin rpy="0 0 0" xyz="0.168 0 0.06"/>
    <parent link="upper_base_link"/>
    <child link="laser"/>
  </joint>
  <!-- Import all Gazebo-customization elements, including Gazebo colors, sensors, controller -->
  <gazebo>
    <plugin filename="libgazebo_ros_control.so" name="gazebo_ros_control">
      <robotNamespace>/mybot_xacro</robotNamespace>
    </plugin>
  </gazebo>
  <gazebo reference="base_link">
    <material>Gazebo/Orange</material>
  </gazebo>
  <gazebo reference="wheel_1">
    <!-- remove friction      
	<mu1>0.0</mu1> 
        <mu2>0.0</mu2>-->
    <!-- -->
    <mu1 value="0.0"/>
    <mu2 value="0.0"/>
    <material>Gazebo/Black</material>
  </gazebo>
  <gazebo reference="wheel_2">
    <material>Gazebo/Black</material>
    <!--
 	<mu1>1000000.0</mu1>
 	<mu2>1000000.0</mu2>
	-->
    <mu1>1000000.0</mu1>
    <mu2>1000000.0</mu2>
    <kp>1000000.0</kp>
    <!--kd>0.5</kd-->
    <kd>100</kd>
    <minDepth>0.001</minDepth>
    <maxVel>1.0</maxVel>
  </gazebo>
  <gazebo reference="wheel_3">
    <!-- remove friction 
	<mu1>0.0</mu1> 
        <mu2>0.0</mu2> -->
    <!-- -->
    <mu1 value="0.0"/>
    <mu2 value="0.0"/>
    <material>Gazebo/Black</material>
  </gazebo>
  <gazebo reference="wheel_4">
    <material>Gazebo/Black</material>
    <mu1>1000000.0</mu1>
    <mu2>1000000.0</mu2>
    <kp>1000000.0</kp>
    <!--kd>0.5</kd-->
    <kd>100.0</kd>
    <minDepth>0.001</minDepth>
    <maxVel>1.0</maxVel>
  </gazebo>

  <gazebo reference="laser">
      <material>Gazebo/Grey</material>
      <sensor type="gpu_ray" name="head_hokuyo_sensor">
          <pose>0 0 0 0 0 0</pose>
          <visualize>true</visualize>
          <update_rate>40</update_rate>
          <ray>
              <scan>
                  <horizontal>
                      <samples>720</samples>
                      <resolution>1</resolution>
                      <min_angle>-2.268928028</min_angle>
                      <max_angle>2.268928028</max_angle>    <!--6.2831184 -->
                  </horizontal>
              </scan>
              <range>
                  <min>0.1</min>
                  <max>12</max>
                  <resolution>0.01</resolution>
              </range>
              <noise>
                  <type>gaussian</type>
                  <mean>0.0</mean>
                  <stddev>0.01</stddev>
              </noise>
          </ray>
          <plugin name="gazebo_ros_head_hokuyo_controller" filename="libgazebo_ros_gpu_laser.so">
              <robotNamespace>/</robotNamespace>
              <topicName>/scan</topicName>
              <frameName>laser</frameName>
          </plugin>
      </sensor>
  </gazebo>

  <!-- WHEELS -->
  <gazebo>
    <plugin filename="libgazebo_ros_diff_drive.so" name="differential_drive_controller">
      <rosDebugLevel>Debug</rosDebugLevel>
      <publishWheelTF>true</publishWheelTF>
      <!--publishTf>1</publishTf-->
      <publishWheelJointState>flase</publishWheelJointState>
      <alwaysOn>true</alwaysOn>
      <updateRate>100</updateRate>
      <leftJoint>base_to_wheel4</leftJoint>
      <rightJoint>base_to_wheel2</rightJoint>
      <wheelSeparation>0.390</wheelSeparation>
      <wheelDiameter>0.155</wheelDiameter>
      <wheelTorque>30</wheelTorque>
      <wheelAcceleration>0.25</wheelAcceleration>
      <!-- roslaunch turtlebot_teleop keyboard_teleop.launch 
    <commandTopic>/eddie/command_velocity</commandTopic>
    -->
      <!-- -->
      <commandTopic>cmd_vel</commandTopic>
      <odometryTopic>odom</odometryTopic>
      <odometryFrame>odom</odometryFrame>
      <!--odometrySource>1</odometrySource-->
      <robotBaseFrame>base_footprint</robotBaseFrame>
    </plugin>
  </gazebo>

  <!-- Add view camera - working -->
  <joint name="view_camera_joint" type="continuous">
    <origin rpy="0 1.570796 0" xyz="0 0 6"/>
    <parent link="kinect_base_link"/>
    <child link="view_camera_link"/>
    <!-- use the following line and type="continuous" to fix the angle of the view camera -->
    <axis xyz="1 0 0"/>
  </joint>
  <link name="view_camera_link">
    <inertial>
      <!-- <mass value="0" /> -->
      <mass value="1e-5"/>
      <origin rpy="0 0 0" xyz="0 0 0"/>
      <inertia ixx="1e-6" ixy="0" ixz="0" iyy="1e-6" iyz="0" izz="1e-6"/>
    </inertial>
  </link>
  <gazebo reference="view_camera_link">
    <sensor name="view_camera" type="camera">
      <update_rate>30.0</update_rate>
      <camera name="head">
        <!--horizontal_fov>1.3962634</horizontal_fov-->
        <image>
          <!-- 960x540, 640x480, 800x600-->
          <width>800</width>
          <height>800</height>
          <format>R8G8B8</format>
        </image>
        <clip>
          <near>0.02</near>
          <far>300</far>
        </clip>
        <noise>
          <type>gaussian</type>
          <mean>0.0</mean>
          <stddev>0.007</stddev>
        </noise>
      </camera>
      <plugin filename="libgazebo_ros_camera.so" name="camera_controller">
        <alwaysOn>true</alwaysOn>
        <updateRate>25.0</updateRate>
        <cameraName>view_camera</cameraName>
        <imageTopicName>image_raw</imageTopicName>
        <cameraInfoTopicName>camera_info</cameraInfoTopicName>
        <frameName>view_camera_link</frameName>
        <CxPrime>320.5</CxPrime>
        <Cx>320.5</Cx>
        <Cy>240.5</Cy>
        <!-- image_width / (2*tan(hfov_radian /2)) -->
        <!-- 320 for wide and 772.55 for narrow stereo camera -->
        <focal_length>320</focal_length>
        <distortion_k1>0.0</distortion_k1>
        <distortion_k2>0.0</distortion_k2>
        <distortion_k3>0.0</distortion_k3>
        <distortion_t1>0.0</distortion_t1>
        <distortion_t2>0.0</distortion_t2>
      </plugin>
    </sensor>
    <!--turnGravityOff>true</turnGravityOff-->
    <material>Gazebo/Blue</material>
  </gazebo>
  <!--xacro:property name="height_torso" value="0.625" /-->
  <link name="base_footprint">
    <visual>
      <geometry>
        <box size="0.001 0.001 0.001"/>
      </geometry>
      <origin rpy="0 0 0" xyz="0 0 0"/>
      <!--origin rpy="0 0 -0.784900" xyz="0 0 0"/-->
    </visual>
    <inertial>
      <mass value="0.0001"/>
      <inertia ixx="1.0" ixy="0.0" ixz="0.0" iyy="1.0" iyz="0.0" izz="1.0"/>
    </inertial>
  </link>
  <gazebo reference="base_footprint">
    <material>Gazebo/Green</material>
    <turnGravityOff>false</turnGravityOff>
  </gazebo>
  <joint name="base_footprint_joint" type="fixed">
    <origin xyz="0 0 0"/>
    <parent link="base_footprint"/>
    <child link="base_link"/>
  </joint>
  <link name="base_link">
    <visual>
      <origin rpy="0 0 0" xyz="0 0 0"/>
      <geometry>
        <cylinder length="0.025" radius="0.225"/>
      </geometry>
      <material name="Orange">
        <color rgba="1.0 0.4 0.0 1.0"/>
      </material>
    </visual>
    <collision>
      <geometry>
        <cylinder length="0.025" radius="0.225"/>
      </geometry>
    </collision>
    <inertial>
      <mass value="10"/>
      <inertia ixx="0.571875" ixy="0" ixz="0" iyy="0.571875" iyz="0" izz="1.1390625"/>
    </inertial>
  </link>
  <!--front wheel -->
  <link name="wheel_1">
    <visual>
      <origin rpy="0 0 0" xyz="0 0 0"/>
      <geometry>
        <sphere radius="0.03875"/>
      </geometry>
      <material name="black">
        <color rgba="0 0 0 1"/>
      </material>
    </visual>
    <collision>
      <origin rpy="0 0 0" xyz="0 0 0"/>
      <geometry>
        <sphere radius="0.03875"/>
      </geometry>
    </collision>
    <inertial>
      <origin rpy="0 0 0" xyz="0 0 0"/>
      <mass value="2"/>
      <inertia ixx="0.00120125" ixy="0" ixz="0" iyy="0.00120125" iyz="0" izz="0.00120125"/>
    </inertial>
  </link>
  <!-- left wheel -->
  <link name="wheel_2">
    <visual>
      <geometry>
        <cylinder length="0.075" radius="0.0775"/>
      </geometry>
      <!-- <origin rpy="0 1.5 0" xyz="-0.1 0.1 0"/> -->
      <origin rpy="0 0 0" xyz="0 0 0"/>
      <material name="black"/>
    </visual>
    <collision>
      <origin rpy="0 0 0" xyz="0 0 0"/>
      <geometry>
        <cylinder length="0.075" radius="0.0775"/>
      </geometry>
    </collision>
    <inertial>
      <mass value="2"/>
      <inertia ixx="0.003940625" ixy="0" ixz="0" iyy="0.003940625" iyz="0" izz="0.00600625"/>
    </inertial>
  </link>
  <!-- back wheel -->
  <link name="wheel_3">
    <visual>
      <origin rpy="0 0 0" xyz="0 0 0"/>
      <geometry>
        <sphere radius="0.03875"/>
      </geometry>
      <material name="black">
        <color rgba="0 0 0 1"/>
      </material>
    </visual>
    <collision>
      <origin rpy="0 0 0" xyz="0 0 0"/>
      <geometry>
        <sphere radius="0.03875"/>
      </geometry>
    </collision>
    <inertial>
      <origin rpy="0 0 0" xyz="0 0 0"/>
      <mass value="2"/>
      <inertia ixx="0.00120125" ixy="0" ixz="0" iyy="0.00120125" iyz="0" izz="0.00120125"/>
    </inertial>
  </link>
  <!-- right wheel -->
  <link name="wheel_4">
    <visual>
      <geometry>
        <cylinder length="0.075" radius="0.0775"/>
      </geometry>
      <!--	<origin rpy="0 1.5 0" xyz="-0.1 -0.1 0"/> -->
      <origin rpy="0 0 0" xyz="0 0 0"/>
      <material name="black"/>
    </visual>
    <collision>
      <origin rpy="0 0 0" xyz="0 0 0"/>
      <geometry>
        <cylinder length="0.075" radius="0.0775"/>
      </geometry>
    </collision>
    <inertial>
      <mass value="2"/>
      <inertia ixx="0.003940625" ixy="0" ixz="0" iyy="0.003940625" iyz="0" izz="0.00600625"/>
    </inertial>
  </link>
  <link name="cpu_link">
    <visual>
      <geometry>
        <box size="0.35 .19 0.095"/>
      </geometry>
      <origin rpy="0 0 0" xyz="0 0 0.0475"/>
      <material name="Cyan2">
        <color rgba="0 0.7 0.7 1.0"/>
      </material>
    </visual>
    <collision>
      <origin rpy="0 0 0" xyz="0 0 0.0475"/>
      <geometry>
        <box size="0.35 .19 0.095"/>
      </geometry>
    </collision>
    <inertial>
      <mass value="2"/>
      <inertia ixx="1.0" ixy="0.0" ixz="0.0" iyy="1.0" iyz="0.0" izz="1.0"/>
    </inertial>
  </link>
  <link name="upper_base_link">
    <visual>
      <origin rpy="0 0 0" xyz="0 0 0.0125"/>
      <geometry>
        <cylinder length="0.025" radius="0.225"/>
      </geometry>
      <material name="Orange">
        <color rgba="1.0 0.4 0.0 1.0"/>
      </material>
    </visual>
    <collision>
      <origin rpy="0 0 0" xyz="0 0 0.0125"/>
      <geometry>
        <cylinder length="0.025" radius="0.225"/>
      </geometry>
    </collision>
    <inertial>
      <mass value="1"/>
      <inertia ixx="1.0" ixy="0.0" ixz="0.0" iyy="1.0" iyz="0.0" izz="1.0"/>
    </inertial>
  </link>
  <link name="torso_link">
    <visual>
      <origin rpy="0 0 0" xyz="0 0 0.3625"/>
      <geometry>
        <box size="0.05 0.1 0.725"/>
      </geometry>
      <material name="Yellow2">
        <color rgba="0.8 0.8 0 1.0"/>
      </material>
    </visual>
    <collision>
      <origin rpy="0 0 0" xyz="0 0 0.3625"/>
      <geometry>
        <box size="0.05 0.1 0.725"/>
      </geometry>
    </collision>
    <inertial>
      <mass value="1"/>
      <inertia ixx="1.0" ixy="0.0" ixz="0.0" iyy="1.0" iyz="0.0" izz="1.0"/>
    </inertial>
  </link>
  <link name="right_torso_link">
    <visual>
      <origin rpy="0 0 0" xyz="0 0 0.3625"/>
      <geometry>
        <box size="0.05 0.025 0.725"/>
      </geometry>
      <material name="Grey2">
        <color rgba="0.6 0.6 0.6 1.0"/>
      </material>
    </visual>
    <collision>
      <origin rpy="0 0 0" xyz="0 0 0.3625"/>
      <geometry>
        <box size="0.05 0.1 0.725"/>
      </geometry>
    </collision>
    <inertial>
      <mass value="1"/>
      <inertia ixx="1.0" ixy="0.0" ixz="0.0" iyy="1.0" iyz="0.0" izz="1.0"/>
    </inertial>
  </link>
  <link name="left_torso_link">
    <visual>
      <origin rpy="0 0 0" xyz="0 0 0.3625"/>
      <geometry>
        <box size="0.05 0.025 0.725"/>
      </geometry>
      <material name="Grey2">
        <color rgba="0.6 0.6 0.6 1.0"/>
      </material>
    </visual>
    <collision>
      <origin rpy="0 0 0" xyz="0 0 0.3625"/>
      <geometry>
        <box size="0.05 0.1 0.725"/>
      </geometry>
    </collision>
    <inertial>
      <mass value="1"/>
      <inertia ixx="1.0" ixy="0.0" ixz="0.0" iyy="1.0" iyz="0.0" izz="1.0"/>
    </inertial>
  </link>
  <link name="top_torso_link">
    <visual>
      <origin rpy="0 0 0" xyz="0 0 0.0125"/>
      <geometry>
        <box size="0.05 0.175 0.025"/>
      </geometry>
      <material name="Grey2">
        <color rgba="0.6 0.6 0.6 1.0"/>
      </material>
    </visual>
    <collision>
      <origin rpy="0 0 0" xyz="0 0 0.0125"/>
      <geometry>
        <box size="0.05 0.125 0.025"/>
      </geometry>
    </collision>
    <inertial>
      <mass value="0.125"/>
      <inertia ixx="1.0" ixy="0.0" ixz="0.0" iyy="1.0" iyz="0.0" izz="1.0"/>
    </inertial>
  </link>
  <link name="head_pan_link">
    <visual>
      <origin rpy="0 0 0" xyz="0 0 0.03"/>
      <geometry>
        <box size="0.05 0.045 0.06"/>
      </geometry>
      <material name="Green1">
        <color rgba="0 1 0 1.0"/>
      </material>
    </visual>
    <collision>
      <origin rpy="0 0 0" xyz="0 0 0.03"/>
      <geometry>
        <box size="0.05 0.045 0.06"/>
      </geometry>
    </collision>
    <inertial>
      <mass value="0.125"/>
      <inertia ixx="1.0" ixy="0.0" ixz="0.0" iyy="1.0" iyz="0.0" izz="1.0"/>
    </inertial>
  </link>
  <link name="head_tilt_link">
    <visual>
      <origin rpy="0 0 0" xyz="0 0 0.0225"/>
      <geometry>
        <box size="0.03 0.038 0.045"/>
      </geometry>
      <material name="Green1">
        <color rgba="0 1 0 1.0"/>
      </material>
    </visual>
    <collision>
      <origin rpy="0 0 0" xyz="0 0 0.0225"/>
      <geometry>
        <box size="0.03 0.038 0.045"/>
      </geometry>
    </collision>
    <inertial>
      <mass value="0.125"/>
      <inertia ixx="1.0" ixy="0.0" ixz="0.0" iyy="1.0" iyz="0.0" izz="1.0"/>
    </inertial>
  </link>
  <link name="kinect_base_link">
    <visual>
      <origin rpy="0 0 0" xyz="0 0 0.0125"/>
      <geometry>
        <box size="0.06 0.065 0.025"/>
      </geometry>
      <material name="Green3">
        <color rgba="0.1 0.5 0.1 1.0"/>
      </material>
    </visual>
    <collision>
      <geometry>
        <box size="0.06 0.065 0.025"/>
      </geometry>
    </collision>
    <inertial>
      <mass value="0.125"/>
      <inertia ixx="1.0" ixy="0.0" ixz="0.0" iyy="1.0" iyz="0.0" izz="1.0"/>
    </inertial>
  </link>
  <link name="screen_link">
    <visual>
      <origin rpy="0 -0.5 0" xyz="0.06 0 -0.11"/>
      <geometry>
        <box size="0.01 0.3 0.16"/>
      </geometry>
      <material name="Grey3">
        <color rgba="0.2 0.2 0.2 1.0"/>
      </material>
    </visual>
    <collision>
      <origin rpy="0 -0.5 0" xyz="0.06 0 -0.11"/>
      <geometry>
        <box size="0.01 0.3 0.16"/>
      </geometry>
    </collision>
    <inertial>
      <mass value="0.125"/>
      <inertia ixx="1.0" ixy="0.0" ixz="0.0" iyy="1.0" iyz="0.0" izz="1.0"/>
    </inertial>
  </link>
  <!-- -->
  <joint name="base_to_wheel1" type="continuous">
    <parent link="base_link"/>
    <child link="wheel_1"/>
   
    <origin rpy="0 0 0" xyz="0.18 0 -0.03865234375"/>
    <axis xyz="0 0 1"/>
  </joint>
  <joint name="base_to_wheel2" type="continuous">
    <axis xyz="0 0 1"/>
    <anchor xyz="0 0 0"/>
    <limit effort="100" velocity="100"/>
    <parent link="base_link"/>
    <child link="wheel_2"/>
    <origin rpy="-1.5707 0 0" xyz="0 -0.195 0"/>
  </joint>
  <!-- -->
  <joint name="base_to_wheel3" type="continuous">
    <parent link="base_link"/>
    <axis xyz="0 0 1"/>
    <child link="wheel_3"/>
    <!--added length_base/32 to get the contact of the wheel with the floor -->
    <origin rpy="0 0 0" xyz="-0.18 0 -0.03865234375"/>
  </joint>
  <joint name="base_to_wheel4" type="continuous">
    <parent link="base_link"/>
    <axis xyz="0 0 1"/>
    <child link="wheel_4"/>
    <origin rpy="-1.5707 0 0" xyz="0 0.195 0"/>
  </joint>
  <joint name="cpu_base_joint" type="fixed">
    <origin xyz="0 0 0"/>
    <parent link="base_link"/>
    <child link="cpu_link"/>
  </joint>
  <joint name="upper_base_cpu_joint" type="fixed">
    <origin xyz="0 0 0.095"/>
    <parent link="cpu_link"/>
    <child link="upper_base_link"/>
  </joint>
  <joint name="torso_upper_base_joint" type="fixed">
    <origin xyz="0 0 0.025"/>
    <parent link="upper_base_link"/>
    <child link="torso_link"/>
  </joint>
  <joint name="right_torso_upper_base_joint" type="fixed">
    <origin xyz="0 -0.075 0.025"/>
    <parent link="upper_base_link"/>
    <child link="right_torso_link"/>
  </joint>
  <joint name="left_torso_upper_base_joint" type="fixed">
    <parent link="upper_base_link"/>
    <child link="left_torso_link"/>
    <origin xyz="0 0.075 0.025"/>
  </joint>
  <joint name="top_torso_torso_joint" type="fixed">
    <parent link="torso_link"/>
    <child link="top_torso_link"/>
    <origin xyz="0 0 0.725"/>
  </joint>
  <joint name="head_pan_servo" type="fixed">
    <parent link="top_torso_link"/>
    <child link="head_pan_link"/>
    <origin rpy="0 0 0" xyz="0 0 0.025"/>
  </joint>
  <joint name="head_pan_joint" type="fixed">
    <parent link="head_pan_link"/>
    <child link="head_tilt_link"/>
    <origin rpy="0 0 0" xyz="0 0 0.06"/>
  </joint>
  <joint name="kinect_base_joint" type="fixed">
    <parent link="head_tilt_link"/>
    <child link="kinect_base_link"/>
    <origin rpy="0 0 0" xyz="0 0 0.045"/>
  </joint>
  <joint name="screen_joint" type="fixed">
    <parent link="top_torso_link"/>
    <child link="screen_link"/>
    <origin rpy="0 0 0" xyz="0 0 0.025"/>
  </joint>
     
</robot>

